Workbook
Name ahxbqays: [1]Sheet2!$F$2:$F$9
Name AREA: Sheet2!$A$2:$A$4
Name BLOOD: Sheet2!$F$2:$F$9
Name DD: [2]Sheet2!$C$2:$C$47
Name DESIGNATION: Sheet2!$D$2:$D$28
Name EDUCATION: Sheet2!$E$2:$E$12
Name FF: [3]Sheet2!$E$2:$E$12
Name FFF: [3]Sheet2!$B$2:$B$20
Name GGG: [3]Sheet2!$C$2:$C$47
Name H: [4]Sheet2!$H$2:$H$18
Name HHH: [3]Sheet2!$A$2:$A$4
Name lll: [5]Sheet2!$C$2:$C$47
Name ooo: [5]Sheet2!$B$2:$B$20
Name qqq: [5]Sheet2!$D$2:$D$28
Name REASON: Sheet2!$H$2:$H$18
Name RELATION: Sheet2!$G$2:$G$11
Name TERRITORY: Sheet2!$B$2:$B$20
Name TOWN: Sheet2!$C$2:$C$47
Name uuu: [5]Sheet2!$H$2:$H$18
Name yyyy: [5]Sheet2!$E$2:$E$12

Sheet Don't Delete
C2: AREA | D2: TERRITORY | E2: TOWN | F2: GRADE | J2: O+(POSITIVE)
B3: CENTRAL SOUTH | C3: DHAKA NORTH SALES AREA | D3: BOSHUNDHARA | E3: BOSHUNDHARA | F3: GRADE-1 | G3: MANAGER ADMIN | H3: BELOW SSC | J3: O-(NEGATIVE)
B4: CENTRAL SOUTH | C4: DHAKA METRO SOUTH SALES AREA | D4: TEJGAON | E4: TEJGAON | F4: GRADE-2 | G4: MANAGER OPS | H4: SSC | J4: A+(POSITIVE)
B5: KHULNA | C5: DHAKA METRO NORTH SALES AREA | D5: UTTARA | E5: UTTARA | F5: GRADE-3 | G5: FSE | H5: HSC | J5: A-(NEGATIVE)
B6: BOGRA | C6: NARAYANGANJ SALES AREA | D6: MALIBAGH | E6: BASABO | F6: GRADE-4 | G6: SSO | H6: BA | J6: B+(POSITIVE)
B7: CHITTAGONG | C7: MODERN TRADE SALES AREA | D7: CHANKHERPOOL | E7: CHANKHERPOOL | G7: WS SSO | H7: BSS | J7: B-(NEGATIVE)
B8: CENTRAL NORTH | C8: KHULNA SALES AREA | D8: JATRABARI | E8: JATRABARI | G8: FEMALE SSO | H8: BBS | J8: AB+(POSITIVE)
B9: SYLHET | C9: BARISAL SALES AREA | D9: WARI | E9: MALIBAGH | G9: CS SSO | H9: BCOM | J9: AB-(NEGATIVE)
C10: KUSHTIA SALES AREA | D10: MIRPUR | E10: WARI | G10: SO | H10: BBA
C11: RAJSHAHI SALES AREA | D11: MOHAMMADPUR | E11: MIRPUR | G11: CS SO | H11: BSC
C12: BOGRA SALES AREA | D12: DARUSSALAM | E12: PALLABI | G12: FEMALE SO | H12: MA
C13: RANGPUR SALES AREA | D13: NARAYANGANJ | E13: MOHAMMADPUR | G13: POOL SO | H13: MSC
C14: CHITTAGONG SALES AREA | D14: ADAMJEE | E14: DARUSSALAM | G14: JSO | H14: MSS
C15: FENI SALES AREA | D15: MUNSHIGANJ | E15: NARAYANGANJ | G15: POOL JSO | H15: MBA
C16: CUMILLA SALES AREA | D16: KARANIGANJ | E16: ADAMJEE | G16: PRO
C17: SAVAR SALES AREA | D17: KARANIGONJ | E17: FATULLAH | G17: PRO [HOUSE]
C18: MYMENSINGH SALES AREA | D18: SMT & SC | E18: MUNSHIGANJ | G18: PPO
C19: TANGAIL SALES AREA | D19: KHULNA METRO | E19: SREENAGAR | G19: PPRO [HOUSE]
C20: SYLHET SALES AREA | D20: SATKHIRA | E20: KARANIGANJ | G20: PDO
C21: NARSINGDHI SALES AREA | D21: JESSORE | E21: ZINJIRA | G21: MALE J. M.
D22: NARAIL | E22: NOWABGANJ | G22: FEMALE J. M.
D23: BAGERHAT | E23: SMT & SHOPPING COMPLEX | G23: MALE S.M.
D24: GOPALGANJ | E24: KHULNA METRO | G24: FEMALE S. M.
D25: BARISAL | E25: RUPSHA | G25: MALE AC. Ex.
D26: PATUAKHALI | E26: KHALISHPUR | G26: FEMALE AC. Ex.
D27: SHARIATPUR | E27: SATHKIRA | G27: MALE CO
D28: MADARIPUR | E28: TALA | G28: FEMALE CO
D29: BHOLA | E29: SHYAMNAGAR | G29: ACCOUNTS
D30: JHALAKATI | E30: KALAROA | G30: FEMALE ACCOUNTS
D31: CHUADANGA | E31: JESSORE | G31: WK
D32: KUSHTIA | E32: CHOWGACHA | G32: ASS. WK
D33: RAJBARI | E33: JHIKARGACHA
D34: FARIDPUR | E34: NARAIL
D35: JHENAIDAH | E35: NOAPARA
D36: MAGURA | E36: MANIRAMPUR
D37: RAJSHAHI | E37: BAGERHAT
D38: NOWHATA | E38: MONGLA
D39: C. N. GANJ | E39: PEROJPUR
D40: JOYPURHAT | E40: GOPALGANJ
D41: GAIBANDHA | E41: TEKARHAT
...

Sheet MAIN DATABASE
A4: SL | B4: TEAM | C4: REGION | D4: AREA | E4: TERRITORY | F4: TOWN [RFF] | G4: SAP CODE | H4: ID EMPLOYEE | I4: EMPLOYEE NAME | J4: DESIGNATION | K4: EDUCATION | L4: DATE OF BIRTH | M4: Age | N4: JOINING DATE IN CURRENT RFF DITRIBUTION | O4: SERVICE TIME IN PREVIOUS RFF DISTRIBUTION | Q4: SERVICE TIME IN CURRENT RFF DISTRIBUTION | S4: YEAR | T4: MONTH | U4: TOTAL EXPERIENCE IN RFF BUSINESS | W4: TENURE | X4: GENDER | Y4: MARITIAL STATUS | Z4: BLOOD GROUP | AA4: FF IDENTIFICATION | AB4: FF IDENTIFICATION NUMBER | AC4: FF CONTACT NUMBER | AD4: NEW/RESIGNATION & TERMINATION | AE4: DATE OF NEW/RESIGNATION & TERMINATION | AF4: REASON OF RESIGNATION & TERMINATION | AG4: FF DISABLITY | AH4: REMARKS FOR EXIT FF
O5: Year | P5: Month | Q5: Year | R5: Month | U5: YEAR | V5: MONTH
B6: CHALLENGER | C6: DHAKA EAST | D6: GULSHAN | E6: DAKKHINKHAN | F6: DAKKHINKHAN | G6: 3400000592 | H6: M5449 | I6: MOHAMMAD SAMSUZZAMAN MOLLIK | J6: FBM
B7: CHALLENGER | C7: DHAKA EAST | D7: GULSHAN | E7: DAKKHINKHAN | F7: DAKKHINKHAN | G7: 3400000592 | H7: M2217 | I7: UJJAL CHANDRA DAS | J7: FBM | N7: 45340
B8: CHALLENGER | C8: DHAKA EAST | D8: GULSHAN | E8: DAKKHINKHAN | F8: DAKKHINKHAN | G8: 3400000592 | H8: M5332 | I8: MD.SUJAN HOSSAIN | J8: DFBM | N8: 45627
B9: CHALLENGER | C9: DHAKA EAST | D9: GULSHAN | E9: DAKKHINKHAN | F9: DAKKHINKHAN | G9: 3400000592 | H9: M2674 | I9: MD. MAHADI HASAN NIPU | J9: SALES OFFICER | N9: 45383
B10: CHALLENGER | C10: DHAKA EAST | D10: GULSHAN | E10: DAKKHINKHAN | F10: DAKKHINKHAN | G10: 3400000592 | H10: M2957 | I10: MD. MAKBUL HOSSAIN | J10: SALES OFFICER | N10: 45431
B11: CHALLENGER | C11: DHAKA EAST | D11: GULSHAN | E11: DAKKHINKHAN | F11: DAKKHINKHAN | G11: 3400000592 | H11: M3301 | I11: SAIDUL RAHMAN | J11: SALES OFFICER | N11: 45479
B12: CHALLENGER | C12: DHAKA EAST | D12: GULSHAN | E12: DAKKHINKHAN | F12: DAKKHINKHAN | G12: 3400000592 | H12: M3880 | I12: MD. FAYSAL AHAMMED BAPPY | J12: SALES OFFICER | N12: 45545
B13: CHALLENGER | C13: DHAKA EAST | D13: GULSHAN | E13: DAKKHINKHAN | F13: DAKKHINKHAN | G13: 3400000592 | H13: M5351 | I13: MD. ROBIUL HASAN | J13: SALES OFFICER | N13: 45597
B14: CHALLENGER | C14: DHAKA EAST | D14: GULSHAN | E14: DAKKHINKHAN | F14: DAKKHINKHAN | G14: 3400000592 | H14: M5648 | I14: AUPU HOWLADER | J14: SALES OFFICER | N14: 45628
B15: CHALLENGER | C15: DHAKA EAST | D15: GULSHAN | E15: DAKKHINKHAN | F15: DAKKHINKHAN | G15: 3400000592 | H15: M5757 | I15: MD. JAHIDUL ISLAM | J15: SALES OFFICER | N15: 45643
B16: CHALLENGER | C16: DHAKA EAST | D16: GULSHAN | E16: DAKKHINKHAN | F16: DAKKHINKHAN | G16: 3400000592 | H16: M6959 | I16: MD. MONIRUL ISLAM | J16: SALES OFFICER | N16: 45686
B17: CHALLENGER | C17: DHAKA EAST | D17: GULSHAN | E17: DAKKHINKHAN | F17: DAKKHINKHAN | G17: 3400000592 | H17: M7495 | I17: HIMEL DHALI | J17: SALES OFFICER | N17: 45719
B18: CHALLENGER | C18: DHAKA EAST | D18: GULSHAN | E18: DAKKHINKHAN | F18: DAKKHINKHAN | G18: 3400000592 | H18: M5917 | I18: MD.JALAL UDDIN RUMI | J18: STORE KEEPER | N18: 45663
... B77: CHALLENGER | C77: DHAKA WEST | D77: MIRPUR | E77: MOHAMMADPUR | F77: MOHAMMADPUR | G77: 3400000559 | H77: M2338 | I77: MD. MIZANUR RAHMAN | J77: ASD | N77: 45349

Sheet Sheet2
A1: AREA | B1: TERRITORY | C1: TOWN | D1: DESIGNATION | E1: EDUCATION | F1: BLOOD | G1: RELATION | H1: REASON | M1: MANAGER OPS | N1: =VLOOKUP(M1,'Don''t Delete'!G:G,1,) -> MANAGER OPS | R1: NID | S1: NID | V1: BBS | W1: BBS | Y1: Promoted To JSO From JSO Pool | Z1: =UPPER(Y1) -> PROMOTED TO JSO FROM JSO POOL | AD1: O+(positive) | AE1: O+(POSITIVE) | AI1: O+(POSITIVE) | AM1: 15353404 | AO1: D06 | XER1: PERFORMANCE ISSUE | XET1: O+(POSITIVE) | XEU1: Below SSC | XEV1: DHAKA SOUTH | XEW1: MALIBAGH | XEX1: BASHABO | XEY1: ACCOUNTS
A2: NARAYANGANJ | B2: NARAYANGANJ | C2: TEJGAON | D2: MANAGER OPS | E2: BELOW SSC | F2: O+(POSITIVE) | G2: FATHER | H2: BEHAVIOR ISSUE | M2: FSE | N2: =VLOOKUP(M2,'Don''t Delete'!G:G,1,) -> FSE | R2: Birth Certificate | S2: BIRTH CERTIFICATE | V2: HSC | W2: HSC | Y2: Promoted To SO From SO Pool | Z2: =UPPER(Y2) -> PROMOTED TO SO FROM SO POOL | AD2: B+(positive) | AE2: B+(POSITIVE) | AI2: O-(NEGATIVE) | AM2: 50256053 | AO2: D09 | XER2: BEHAVIOR ISSUE | XES2: FATHER | XET2: AB-(NEGATIVE) | XEU2: SSC | XEV2: DHAKA SOUTH | XEW2: DARUS-SALAM | XEX2: MALIBAGH | XEY2: MANAGER ADMIN
A3: NARSINGDHI | B3: DAUDKANDI | C3: MALIBAGH | D3: ACCOUNTS | E3: SSC | F3: AB-(NEGATIVE) | G3: MOTHER | H3: PERFORMANCE ISSUE | M3: SO | N3: =VLOOKUP(M3,'Don''t Delete'!G:G,1,) -> SO | V3: BA | W3: BA | Y3: Move to Pool SO from SO | Z3: =UPPER(Y3) -> MOVE TO POOL SO FROM SO | AD3: AB+(Positive) | AE3: AB+(POSITIVE) | AI3: A+(POSITIVE) | AM3: 15143714 | AO3: D47 | XER3: FAMILY ISSUE | XES3: MOTHER | XET3: A+(POSITIVE) | XEU3: HSC | XEV3: NARAYANGONJ | XEW3: MOHAMMADPUR | XEX3: DARUS-SALAM | XEY3: ASS. MANAGER
A4: DHAKA SOUTH | B4: MLIBAGH | C4: BASABO | D4: MANAGER ADMIN | E4: HSC | F4: A+(POSITIVE) | G4: SON | H4: BEHAVIOR ISSUE | M4: WS SSO | N4: =VLOOKUP(M4,'Don''t Delete'!G:G,1,) -> WS SSO | V4: MA | W4: MA | Y4: Promoted from Pool So to SSO (Previous he was a SSO) | Z4: =UPPER(Y4) -> PROMOTED FROM POOL SO TO SSO (PREVIOUS HE WAS A SSO) | AD4: A+(POSITIVE) | AE4: A+(POSITIVE) | AI4: A-(NEGATIVE) | AM4: 50256393 | AO4: D10 | XER4: BETTER OPPORTUNITY | XES4: SON | XET4: B+(POSITIVE) | XEU4: BBA | XEV4: NARSINGDHI | XEW4: NARAYANGANJ | XEX4: MOHAMMADPUR | XEY4: CS SO
B5: BOSHUNDHARA | C5: BOSHUNDHARA | D5: ASS. MANAGER | E5: BBA | F5: B+(POSITIVE) | G5: DAUGHTER | H5: FAMILY ISSUE | M5: SSO | N5: =VLOOKUP(M5,'Don''t Delete'!G:G,1,) -> SSO | V5: B.SC | W5: BSC | Y5: From Pool SO to JSO | Z5: =UPPER(Y5) -> FROM POOL SO TO JSO | AD5: AB-(negative) | AE5: AB-(NEGATIVE) | AI5: B+(POSITIVE) | AM5: 15422765 | AO5: D62 | XER5: PHYSICAL INABILITY | XES5: DAUGHTER | XET5: A-(NEGATIVE) | XEU5: BA | XEV5: CHITTAGONG | XEW5: KARANIGANJ | XEX5: ADAMJEE | XEY5: CS SSO
B6: CHANKHERPOOL | C6: MOHAMMADPUR | D6: CS SO | E6: BA | F6: A-(NEGATIVE) | G6: WIFE | H6: BETTER OPPORTUNITY | M6: POOL SO | N6: =VLOOKUP(M6,'Don''t Delete'!G:G,1,) -> POOL SO | V6: BBA | W6: BBA | Y6: Promoted from Pool So to SO | Z6: =UPPER(Y6) -> PROMOTED FROM POOL SO TO SO | AD6: O-(negative) | AE6: O-(NEGATIVE) | AI6: B-(NEGATIVE) | AM6: 50256052 | AO6: D07 | XER6: DISCIPLINE ISSUE | XES6: WIFE | XET6: AB+(POSITIVE) | XEU6: BBS | XEV6: COMILLA | XEW6: JATRABARI | XEX6: NARAYANGANJ | XEY6: FEMALE AC. EX.
B7: DARUSSALAM | C7: DARUSSALAM | D7: CS SSO | E7: BBS | F7: AB+(POSITIVE) | G7: HUSBAND | H7: PHYSICAL INABILITY | M7: JSO | N7: =VLOOKUP(M7,'Don''t Delete'!G:G,1,) -> JSO | V7: BSS | W7: BSS | Y7: From Pool JSO to JSO | Z7: =UPPER(Y7) -> FROM POOL JSO TO JSO | AD7: B-(NEGATIVE) | AE7: B-(NEGATIVE) | AI7: AB+(POSITIVE) | AM7: 15383457 | AO7: D53 | XER7: GOING ABROAD | XES7: HUSBAND | XET7: O-(NEGATIVE) | XEU7: B.SC | XEV7: SYLHET | XEW7: GHORASAL | XEX7: KARANIGANJ | XEY7: FEMALE CO
B8: GHORASAL | C8: WARI | D8: FEMALE AC. EX. | E8: B.SC | F8: O-(NEGATIVE) | G8: UNCLE | H8: DISCIPLINE ISSUE | M8: POOL JSO | N8: =VLOOKUP(M8,'Don''t Delete'!G:G,1,) -> POOL JSO | V8: SSC | W8: SSC | Y8: From pool JSO to SO | Z8: =UPPER(Y8) -> FROM POOL JSO TO SO | AD8: A-(negative) | AE8: A-(NEGATIVE) | AI8: AB-(NEGATIVE) | AM8: 50256059 | AO8: D14 | XER8: ETHICAL ISSUE | XES8: UNCLE | XET8: B-(NEGATIVE) | XEU8: BSS | XEV8: KHULNA | XEW8: DAUDKANDI | XEX8: NOWABGANJ | XEY8: FEMALE J. M.
B9: JATRABARI | C9: CHANKHERPOOL | D9: FEMALE CO | E9: BSS | F9: B-(NEGATIVE) | G9: AUNTY | H9: GOING ABROAD | M9: MALE CO | N9: =VLOOKUP(M9,'Don''t Delete'!G:G,1,) -> MALE CO | V9: BELOW SSC | W9: BELOW SSC | Y9: From Pool So to SO | Z9: =UPPER(Y9) -> FROM POOL SO TO SO | AD9: O+ (Positive) | AE9: O+(POSITIVE) | AM9: 15383458 | AO9: D54 | XER9: ATTENDANCE ISSUE | XES9: AUNTY | XEU9: MA | XEV9: BARISAL | XEW9: SONARGAON | XEX9: JATRABARI | XEY9: FEMALE S. M.
B10: KARANIGANJ | C10: NARAYANGANJ | D10: FEMALE J. M. | E10: MA | G10: BROTHER | H10: ETHICAL ISSUE | M10: ACCOUNTS | N10: =VLOOKUP(M10,'Don''t Delete'!G:G,1,) -> ACCOUNTS | V10: MBA | W10: MBA | Y10: From SO to JSO | Z10: =UPPER(Y10) -> FROM SO TO JSO | AD10: 0+(POSITIVE) | AE10: O+(POSITIVE) | AM10: 15168991 | AO10: D15 | XER10: COMPLIANCE ISSUE | XES10: BROTHER | XEU10: MBA | XEV10: KUSHTIA | XEW10: SHOPPING COMPLEX | XEX10: GAUSIA | XEY10: FEMALE SO
B11: MOHAMMADPUR | C11: ADAMJEE | D11: FEMALE S. M. | E11: MBA | G11: SISTER | H11: ATTENDANCE ISSUE | M11: MANAGER ADMIN | N11: =VLOOKUP(M11,'Don''t Delete'!G:G,1,) -> MANAGER ADMIN | V11: HSC | W11: HSC | Y11: From JSO to WK | Z11: =UPPER(Y11) -> FROM JSO TO WK | AD11: 0 | AM11: 15383461 | AO11: D55 | XER11: MARKET MANIPULATION | XES11: SISTER | XEU11: B.COM | XEV11: WATER | XEW11: MUNSHIGANJ | XEX11: BANCHARAMPUR | XEY11: FEMALE SSO
B12: NARSINGDHI | C12: KARANIGANJ | D12: FEMALE SO | E12: B.COM | H12: COMPLIANCE ISSUE | M12: WK | N12: =VLOOKUP(M12,'Don''t Delete'!G:G,1,) -> WK | V12: BSC | W12: BSC | Y12: Promoted to JSO to SO | Z12: =UPPER(Y12) -> PROMOTED TO JSO TO SO | AM12: 50256056 | AO12: C17 | XER12: TRADE GIFT OR PAYMENT MISAPPROPRIATION | XEV12: WATER-CHITTAGONG | XEW12: NARSINGDHI | XEX12: DAUDKANDI | XEY12: FSE
B13: MUNSHIGANJ | C13: NOWABGANJ | D13: FEMALE SSO | H13: MARKET MANIPULATION | M13: ASS. WK | N13: =VLOOKUP(M13,'Don''t Delete'!G:G,1,) -> ASS. WK | V13: BCOM | W13: BCOM | Y13: Promoted from JSO to SO | Z13: =UPPER(Y13) -> PROMOTED FROM JSO TO SO | AM13: 15383877 | AO13: C56 | XER13: SALES WITH OUTSIDE THE PARTY WITH COMMISSION | XEV13: MODERN TRADE DISTRIB | XEW13: BOSHUNDHARA | XEX13: SONARGAON | XEY13: JSO
B14: SONARGAON | C14: MUNSHIGANJ | D14: FSE | H14: TRADE GIFT OR PAYMENT MISAPPROPRIATION | M14: PRO | N14: =VLOOKUP(M14,'Don''t Delete'!G:G,1,) -> PRO | V14: MSC | W14: MSC | Y14: Promoted from Pool JSO to SO | Z14: =UPPER(Y14) -> PROMOTED FROM POOL JSO TO SO | AM14: 15383870 | AO14: D57 | XER14: AFTER DELIVERY SHORTAGE | XEV14: MYMENSINGH | XEW14: TEJGAON | XEX14: SMT & SHOPPING COMPLEX | XEY14: MALE AC. EX.
B15: TEJGAON | C15: SREENAGAR | D15: JSO | H15: SALES WITH OUTSIDE THE PARTY WITH COMMISSION | M15: FEMALE CO | N15: =VLOOKUP(M15,'Don''t Delete'!G:G,1,) -> FEMALE CO | V15: MSS | W15: MSS | AM15: 50256061 | AO15: D16 | XER15: PERSONAL ISSUE | XEV15: DHAKA NORTH | XEW15: CHANKHERPOOL | XEX15: MUNSHIGANJ | XEY15: MALE CO
B16: WARI | C16: JATRABARI | D16: MALE AC. EX. | H16: AFTER DELIVERY SHORTAGE | M16: FEMALE ACCOUNTS | N16: =VLOOKUP(M16,'Don''t Delete'!G:G,1,) -> FEMALE ACCOUNTS | AM16: 50256060 | AO16: D11 | XER16: BETTAR OPPORTUNITY | XEV16: TANGAIL | XEW16: WARI | XEX16: SREENAGAR | XEY16: MALE J. M.
C17: SONARGAON | D17: MALE CO | H17: PERSONAL ISSUE | M17: PRO [HOUSE] | N17: =VLOOKUP(M17,'Don''t Delete'!G:G,1,) -> PRO [HOUSE] | AM17: 15383462 | AO17: D56 | XEV17: BOGRA | XEW17: DEWANHAT | XEX17: NARSINGDHI | XEY17: MALE S.M.
C18: DAUDKANDI | D18: MALE J. M. | H18: BETTAR OPPORTUNITY | M18: PPRO [HOUSE] | N18: =VLOOKUP(M18,'Don''t Delete'!G:G,1,) -> PPRO [HOUSE] | AM18: 15430884 | AO18: D64 | XEV18: RANGPUR | XEW18: SITAKUND | XEX18: MONOHORDI | XEY18: PRO [HOUSE]
C19: BANCHARAMPUR | D19: MALE S.M. | AM19: 15393943 | AO19: D31 | XEV19: RAJSHAHI | XEW19: NASIRABAD | XEX19: GHORASAL | XEY19: PRO
C20: NARSINGDHI | D20: PRO [HOUSE] | AM20: 50256058 | AO20: D19 | XEW20: HALISHAHAR | XEX20: BOSHUNDHARA | XEY20: SO
C21: MONOHORDI | D21: PRO | AM21: 50256063 | AO21: D38 | XEW21: HATHAZARI | XEX21: TEJGAON | XEY21: SSO
C22: GHORASAL | D22: SO | AM22: 15506848 | AO22: D13 | XEW22: PATIYA | XEX22: CHANKHERPOOL | XEY22: WS SSO
C23: GAUSIA | D23: SSO | AM23: 15208171 | AO23: D12 | XEW23: COX'S BAZAR | XEX23: WARI | XEY23: WK
C24: SHOPPING COMPLEX | D24: WS SSO | XEW24: LAKSHAM | XEX24: DEWANHAT | XEY24: ASS. WK
C25: BELABO | D25: WK | XEW25: COMILLA | XEX25: CHAKTAI | XEY25: POOL SO
C26: ZINJIRA | D26: ASS. WK | XEW26: CHANDPUR | XEX26: SITAKUND | XEY26: POOL JSO
C27: ARAIHAZAR | D27: POOL SO | XEW27: NOAKHALI | XEX27: KAPTAI
D28: POOL JSO | XEW28: FENI | XEX28: SANDWIP
XEW29: SYLHET METRO | XEX29: NASIRABAD
XEW30: SUNAMGANJ | XEX30: HALISHAHAR
XEW31: SOUTH SURMA | XEX31: HATHAZARI
XEW32: SHAYESTAGANJ | XEX32: RANGAMATI
XEW33: M. BAZAR | XEX33: KHAGRACHARI
XEW34: B. BARIA | XEX34: ANWARA
XEW35: BHAIRAB | XEX35: BANDARBAN
XEW36: KHULNA METRO | XEX36: PATIYA
XEW37: SATHKIRA | XEX37: COX'S BAZAR
XEW38: JESSORE | XEX38: CHAKARIA
XEW39: NARAIL | XEX39: TEKNAF
XEW40: GOPALGANJ | XEX40: LAKSHAM
...

Sheet Summary
B1: Tgt vs Ach | J1: Database
B2: Town | C2: MAN-OPS | D2: FSE | E2: WS SSO | F2: SSO | G2: SO | H2: JSO | I2: Total | J2: MANAGER OPS | K2: FSE | L2: WS SSO | M2: SSO | N2: SO | O2: JSO | P2: POOL SO | Q2: POOL JSO | S2: POOL
B3: TONGI | I3: =SUM(C3:H3) -> 0 | J3: =SUMIFS('MAIN DATABASE'!#REF!,'MAIN DATABASE'!$F:$F,Summary!$B3,'MAIN DATABASE'!$J:$J,Summary!J$2) -> #REF! | K3: =SUMIFS('MAIN DATABASE'!#REF!,'MAIN DATABASE'!$F:$F,Summary!$B3,'MAIN DATABASE'!$J:$J,Summary!K$2) -> #REF! | L3: =SUMIFS('MAIN DATABASE'!#REF!,'MAIN DATABASE'!$F:$F,Summary!$B3,'MAIN DATABASE'!$J:$J,Summary!L$2) -> #REF! | M3: =SUMIFS('MAIN DATABASE'!#REF!,'MAIN DATABASE'!$F:$F,Summary!$B3,'MAIN DATABASE'!$J:$J,Summary!M$2) -> #REF! | N3: =SUMIFS('MAIN DATABASE'!#REF!,'MAIN DATABASE'!$F:$F,Summary!$B3,'MAIN DATABASE'!$J:$J,Summary!N$2) -> #REF! | O3: =SUMIFS('MAIN DATABASE'!#REF!,'MAIN DATABASE'!$F:$F,Summary!$B3,'MAIN DATABASE'!$J:$J,Summary!O$2) -> #REF! | P3: =SUMIFS('MAIN DATABASE'!#REF!,'MAIN DATABASE'!$F:$F,Summary!$B3,'MAIN DATABASE'!$J:$J,Summary!P$2) -> #REF! | Q3: =SUMIFS('MAIN DATABASE'!#REF!,'MAIN DATABASE'!$F:$F,Summary!$B3,'MAIN DATABASE'!$J:$J,Summary!Q$2) -> #REF! | R3: =SUM(J3:O3) -> #REF! | S3: =P3+Q3 -> #REF! | T3: =R3+S3 -> #REF! | U3: =I3-R3 -> #REF!
B4: MANIKGANJ | I4: =SUM(C4:H4) -> 0 | J4: =SUMIFS('MAIN DATABASE'!#REF!,'MAIN DATABASE'!$F:$F,Summary!$B4,'MAIN DATABASE'!$J:$J,Summary!J$2) -> #REF! | K4: =SUMIFS('MAIN DATABASE'!#REF!,'MAIN DATABASE'!$F:$F,Summary!$B4,'MAIN DATABASE'!$J:$J,Summary!K$2) -> #REF! | L4: =SUMIFS('MAIN DATABASE'!#REF!,'MAIN DATABASE'!$F:$F,Summary!$B4,'MAIN DATABASE'!$J:$J,Summary!L$2) -> #REF! | M4: =SUMIFS('MAIN DATABASE'!#REF!,'MAIN DATABASE'!$F:$F,Summary!$B4,'MAIN DATABASE'!$J:$J,Summary!M$2) -> #REF! | N4: =SUMIFS('MAIN DATABASE'!#REF!,'MAIN DATABASE'!$F:$F,Summary!$B4,'MAIN DATABASE'!$J:$J,Summary!N$2) -> #REF! | O4: =SUMIFS('MAIN DATABASE'!#REF!,'MAIN DATABASE'!$F:$F,Summary!$B4,'MAIN DATABASE'!$J:$J,Summary!O$2) -> #REF! | P4: =SUMIFS('MAIN DATABASE'!#REF!,'MAIN DATABASE'!$F:$F,Summary!$B4,'MAIN DATABASE'!$J:$J,Summary!P$2) -> #REF! | Q4: =SUMIFS('MAIN DATABASE'!#REF!,'MAIN DATABASE'!$F:$F,Summary!$B4,'MAIN DATABASE'!$J:$J,Summary!Q$2) -> #REF! | R4: =SUM(J4:O4) -> #REF! | S4: =P4+Q4 -> #REF! | T4: =R4+S4 -> #REF! | U4: =I4-R4 -> #REF!
B5: DHAMRAI | I5: =SUM(C5:H5) -> 0 | J5: =SUMIFS('MAIN DATABASE'!#REF!,'MAIN DATABASE'!$F:$F,Summary!$B5,'MAIN DATABASE'!$J:$J,Summary!J$2) -> #REF! | K5: =SUMIFS('MAIN DATABASE'!#REF!,'MAIN DATABASE'!$F:$F,Summary!$B5,'MAIN DATABASE'!$J:$J,Summary!K$2) -> #REF! | L5: =SUMIFS('MAIN DATABASE'!#REF!,'MAIN DATABASE'!$F:$F,Summary!$B5,'MAIN DATABASE'!$J:$J,Summary!L$2) -> #REF! | M5: =SUMIFS('MAIN DATABASE'!#REF!,'MAIN DATABASE'!$F:$F,Summary!$B5,'MAIN DATABASE'!$J:$J,Summary!M$2) -> #REF! | N5: =SUMIFS('MAIN DATABASE'!#REF!,'MAIN DATABASE'!$F:$F,Summary!$B5,'MAIN DATABASE'!$J:$J,Summary!N$2) -> #REF! | O5: =SUMIFS('MAIN DATABASE'!#REF!,'MAIN DATABASE'!$F:$F,Summary!$B5,'MAIN DATABASE'!$J:$J,Summary!O$2) -> #REF! | P5: =SUMIFS('MAIN DATABASE'!#REF!,'MAIN DATABASE'!$F:$F,Summary!$B5,'MAIN DATABASE'!$J:$J,Summary!P$2) -> #REF! | Q5: =SUMIFS('MAIN DATABASE'!#REF!,'MAIN DATABASE'!$F:$F,Summary!$B5,'MAIN DATABASE'!$J:$J,Summary!Q$2) -> #REF! | R5: =SUM(J5:O5) -> #REF! | S5: =P5+Q5 -> #REF! | T5: =R5+S5 -> #REF! | U5: =I5-R5 -> #REF!
B6: SAVAR | I6: =SUM(C6:H6) -> 0 | J6: =SUMIFS('MAIN DATABASE'!#REF!,'MAIN DATABASE'!$F:$F,Summary!$B6,'MAIN DATABASE'!$J:$J,Summary!J$2) -> #REF! | K6: =SUMIFS('MAIN DATABASE'!#REF!,'MAIN DATABASE'!$F:$F,Summary!$B6,'MAIN DATABASE'!$J:$J,Summary!K$2) -> #REF! | L6: =SUMIFS('MAIN DATABASE'!#REF!,'MAIN DATABASE'!$F:$F,Summary!$B6,'MAIN DATABASE'!$J:$J,Summary!L$2) -> #REF! | M6: =SUMIFS('MAIN DATABASE'!#REF!,'MAIN DATABASE'!$F:$F,Summary!$B6,'MAIN DATABASE'!$J:$J,Summary!M$2) -> #REF! | N6: =SUMIFS('MAIN DATABASE'!#REF!,'MAIN DATABASE'!$F:$F,Summary!$B6,'MAIN DATABASE'!$J:$J,Summary!N$2) -> #REF! | O6: =SUMIFS('MAIN DATABASE'!#REF!,'MAIN DATABASE'!$F:$F,Summary!$B6,'MAIN DATABASE'!$J:$J,Summary!O$2) -> #REF! | P6: =SUMIFS('MAIN DATABASE'!#REF!,'MAIN DATABASE'!$F:$F,Summary!$B6,'MAIN DATABASE'!$J:$J,Summary!P$2) -> #REF! | Q6: =SUMIFS('MAIN DATABASE'!#REF!,'MAIN DATABASE'!$F:$F,Summary!$B6,'MAIN DATABASE'!$J:$J,Summary!Q$2) -> #REF! | R6: =SUM(J6:O6) -> #REF! | S6: =P6+Q6 -> #REF! | T6: =R6+S6 -> #REF! | U6: =I6-R6 -> #REF!
B7: DEPZ | I7: =SUM(C7:H7) -> 0 | J7: =SUMIFS('MAIN DATABASE'!#REF!,'MAIN DATABASE'!$F:$F,Summary!$B7,'MAIN DATABASE'!$J:$J,Summary!J$2) -> #REF! | K7: =SUMIFS('MAIN DATABASE'!#REF!,'MAIN DATABASE'!$F:$F,Summary!$B7,'MAIN DATABASE'!$J:$J,Summary!K$2) -> #REF! | L7: =SUMIFS('MAIN DATABASE'!#REF!,'MAIN DATABASE'!$F:$F,Summary!$B7,'MAIN DATABASE'!$J:$J,Summary!L$2) -> #REF! | M7: =SUMIFS('MAIN DATABASE'!#REF!,'MAIN DATABASE'!$F:$F,Summary!$B7,'MAIN DATABASE'!$J:$J,Summary!M$2) -> #REF! | N7: =SUMIFS('MAIN DATABASE'!#REF!,'MAIN DATABASE'!$F:$F,Summary!$B7,'MAIN DATABASE'!$J:$J,Summary!N$2) -> #REF! | O7: =SUMIFS('MAIN DATABASE'!#REF!,'MAIN DATABASE'!$F:$F,Summary!$B7,'MAIN DATABASE'!$J:$J,Summary!O$2) -> #REF! | P7: =SUMIFS('MAIN DATABASE'!#REF!,'MAIN DATABASE'!$F:$F,Summary!$B7,'MAIN DATABASE'!$J:$J,Summary!P$2) -> #REF! | Q7: =SUMIFS('MAIN DATABASE'!#REF!,'MAIN DATABASE'!$F:$F,Summary!$B7,'MAIN DATABASE'!$J:$J,Summary!Q$2) -> #REF! | R7: =SUM(J7:O7) -> #REF! | S7: =P7+Q7 -> #REF! | T7: =R7+S7 -> #REF! | U7: =I7-R7 -> #REF!
B8: KALIAKOIR | I8: =SUM(C8:H8) -> 0 | J8: =SUMIFS('MAIN DATABASE'!#REF!,'MAIN DATABASE'!$F:$F,Summary!$B8,'MAIN DATABASE'!$J:$J,Summary!J$2) -> #REF! | K8: =SUMIFS('MAIN DATABASE'!#REF!,'MAIN DATABASE'!$F:$F,Summary!$B8,'MAIN DATABASE'!$J:$J,Summary!K$2) -> #REF! | L8: =SUMIFS('MAIN DATABASE'!#REF!,'MAIN DATABASE'!$F:$F,Summary!$B8,'MAIN DATABASE'!$J:$J,Summary!L$2) -> #REF! | M8: =SUMIFS('MAIN DATABASE'!#REF!,'MAIN DATABASE'!$F:$F,Summary!$B8,'MAIN DATABASE'!$J:$J,Summary!M$2) -> #REF! | N8: =SUMIFS('MAIN DATABASE'!#REF!,'MAIN DATABASE'!$F:$F,Summary!$B8,'MAIN DATABASE'!$J:$J,Summary!N$2) -> #REF! | O8: =SUMIFS('MAIN DATABASE'!#REF!,'MAIN DATABASE'!$F:$F,Summary!$B8,'MAIN DATABASE'!$J:$J,Summary!O$2) -> #REF! | P8: =SUMIFS('MAIN DATABASE'!#REF!,'MAIN DATABASE'!$F:$F,Summary!$B8,'MAIN DATABASE'!$J:$J,Summary!P$2) -> #REF! | Q8: =SUMIFS('MAIN DATABASE'!#REF!,'MAIN DATABASE'!$F:$F,Summary!$B8,'MAIN DATABASE'!$J:$J,Summary!Q$2) -> #REF! | R8: =SUM(J8:O8) -> #REF! | S8: =P8+Q8 -> #REF! | T8: =R8+S8 -> #REF! | U8: =I8-R8 -> #REF!
B9: SHAKHIPUR | I9: =SUM(C9:H9) -> 0 | J9: =SUMIFS('MAIN DATABASE'!#REF!,'MAIN DATABASE'!$F:$F,Summary!$B9,'MAIN DATABASE'!$J:$J,Summary!J$2) -> #REF! | K9: =SUMIFS('MAIN DATABASE'!#REF!,'MAIN DATABASE'!$F:$F,Summary!$B9,'MAIN DATABASE'!$J:$J,Summary!K$2) -> #REF! | L9: =SUMIFS('MAIN DATABASE'!#REF!,'MAIN DATABASE'!$F:$F,Summary!$B9,'MAIN DATABASE'!$J:$J,Summary!L$2) -> #REF! | M9: =SUMIFS('MAIN DATABASE'!#REF!,'MAIN DATABASE'!$F:$F,Summary!$B9,'MAIN DATABASE'!$J:$J,Summary!M$2) -> #REF! | N9: =SUMIFS('MAIN DATABASE'!#REF!,'MAIN DATABASE'!$F:$F,Summary!$B9,'MAIN DATABASE'!$J:$J,Summary!N$2) -> #REF! | O9: =SUMIFS('MAIN DATABASE'!#REF!,'MAIN DATABASE'!$F:$F,Summary!$B9,'MAIN DATABASE'!$J:$J,Summary!O$2) -> #REF! | P9: =SUMIFS('MAIN DATABASE'!#REF!,'MAIN DATABASE'!$F:$F,Summary!$B9,'MAIN DATABASE'!$J:$J,Summary!P$2) -> #REF! | Q9: =SUMIFS('MAIN DATABASE'!#REF!,'MAIN DATABASE'!$F:$F,Summary!$B9,'MAIN DATABASE'!$J:$J,Summary!Q$2) -> #REF! | R9: =SUM(J9:O9) -> #REF! | S9: =P9+Q9 -> #REF! | T9: =R9+S9 -> #REF! | U9: =I9-R9 -> #REF!
B10: TANGAIL | I10: =SUM(C10:H10) -> 0 | J10: =SUMIFS('MAIN DATABASE'!#REF!,'MAIN DATABASE'!$F:$F,Summary!$B10,'MAIN DATABASE'!$J:$J,Summary!J$2) -> #REF! | K10: =SUMIFS('MAIN DATABASE'!#REF!,'MAIN DATABASE'!$F:$F,Summary!$B10,'MAIN DATABASE'!$J:$J,Summary!K$2) -> #REF! | L10: =SUMIFS('MAIN DATABASE'!#REF!,'MAIN DATABASE'!$F:$F,Summary!$B10,'MAIN DATABASE'!$J:$J,Summary!L$2) -> #REF! | M10: =SUMIFS('MAIN DATABASE'!#REF!,'MAIN DATABASE'!$F:$F,Summary!$B10,'MAIN DATABASE'!$J:$J,Summary!M$2) -> #REF! | N10: =SUMIFS('MAIN DATABASE'!#REF!,'MAIN DATABASE'!$F:$F,Summary!$B10,'MAIN DATABASE'!$J:$J,Summary!N$2) -> #REF! | O10: =SUMIFS('MAIN DATABASE'!#REF!,'MAIN DATABASE'!$F:$F,Summary!$B10,'MAIN DATABASE'!$J:$J,Summary!O$2) -> #REF! | P10: =SUMIFS('MAIN DATABASE'!#REF!,'MAIN DATABASE'!$F:$F,Summary!$B10,'MAIN DATABASE'!$J:$J,Summary!P$2) -> #REF! | Q10: =SUMIFS('MAIN DATABASE'!#REF!,'MAIN DATABASE'!$F:$F,Summary!$B10,'MAIN DATABASE'!$J:$J,Summary!Q$2) -> #REF! | R10: =SUM(J10:O10) -> #REF! | S10: =P10+Q10 -> #REF! | T10: =R10+S10 -> #REF! | U10: =I10-R10 -> #REF!
B11: JAMALPUR | I11: =SUM(C11:H11) -> 0 | J11: =SUMIFS('MAIN DATABASE'!#REF!,'MAIN DATABASE'!$F:$F,Summary!$B11,'MAIN DATABASE'!$J:$J,Summary!J$2) -> #REF! | K11: =SUMIFS('MAIN DATABASE'!#REF!,'MAIN DATABASE'!$F:$F,Summary!$B11,'MAIN DATABASE'!$J:$J,Summary!K$2) -> #REF! | L11: =SUMIFS('MAIN DATABASE'!#REF!,'MAIN DATABASE'!$F:$F,Summary!$B11,'MAIN DATABASE'!$J:$J,Summary!L$2) -> #REF! | M11: =SUMIFS('MAIN DATABASE'!#REF!,'MAIN DATABASE'!$F:$F,Summary!$B11,'MAIN DATABASE'!$J:$J,Summary!M$2) -> #REF! | N11: =SUMIFS('MAIN DATABASE'!#REF!,'MAIN DATABASE'!$F:$F,Summary!$B11,'MAIN DATABASE'!$J:$J,Summary!N$2) -> #REF! | O11: =SUMIFS('MAIN DATABASE'!#REF!,'MAIN DATABASE'!$F:$F,Summary!$B11,'MAIN DATABASE'!$J:$J,Summary!O$2) -> #REF! | P11: =SUMIFS('MAIN DATABASE'!#REF!,'MAIN DATABASE'!$F:$F,Summary!$B11,'MAIN DATABASE'!$J:$J,Summary!P$2) -> #REF! | Q11: =SUMIFS('MAIN DATABASE'!#REF!,'MAIN DATABASE'!$F:$F,Summary!$B11,'MAIN DATABASE'!$J:$J,Summary!Q$2) -> #REF! | R11: =SUM(J11:O11) -> #REF! | S11: =P11+Q11 -> #REF! | T11: =R11+S11 -> #REF! | U11: =I11-R11 -> #REF!
B12: SARISHABARI | I12: =SUM(C12:H12) -> 0 | J12: =SUMIFS('MAIN DATABASE'!#REF!,'MAIN DATABASE'!$F:$F,Summary!$B12,'MAIN DATABASE'!$J:$J,Summary!J$2) -> #REF! | K12: =SUMIFS('MAIN DATABASE'!#REF!,'MAIN DATABASE'!$F:$F,Summary!$B12,'MAIN DATABASE'!$J:$J,Summary!K$2) -> #REF! | L12: =SUMIFS('MAIN DATABASE'!#REF!,'MAIN DATABASE'!$F:$F,Summary!$B12,'MAIN DATABASE'!$J:$J,Summary!L$2) -> #REF! | M12: =SUMIFS('MAIN DATABASE'!#REF!,'MAIN DATABASE'!$F:$F,Summary!$B12,'MAIN DATABASE'!$J:$J,Summary!M$2) -> #REF! | N12: =SUMIFS('MAIN DATABASE'!#REF!,'MAIN DATABASE'!$F:$F,Summary!$B12,'MAIN DATABASE'!$J:$J,Summary!N$2) -> #REF! | O12: =SUMIFS('MAIN DATABASE'!#REF!,'MAIN DATABASE'!$F:$F,Summary!$B12,'MAIN DATABASE'!$J:$J,Summary!O$2) -> #REF! | P12: =SUMIFS('MAIN DATABASE'!#REF!,'MAIN DATABASE'!$F:$F,Summary!$B12,'MAIN DATABASE'!$J:$J,Summary!P$2) -> #REF! | Q12: =SUMIFS('MAIN DATABASE'!#REF!,'MAIN DATABASE'!$F:$F,Summary!$B12,'MAIN DATABASE'!$J:$J,Summary!Q$2) -> #REF! | R12: =SUM(J12:O12) -> #REF! | S12: =P12+Q12 -> #REF! | T12: =R12+S12 -> #REF! | U12: =I12-R12 -> #REF!
B13: MODHUPUR | I13: =SUM(C13:H13) -> 0 | J13: =SUMIFS('MAIN DATABASE'!#REF!,'MAIN DATABASE'!$F:$F,Summary!$B13,'MAIN DATABASE'!$J:$J,Summary!J$2) -> #REF! | K13: =SUMIFS('MAIN DATABASE'!#REF!,'MAIN DATABASE'!$F:$F,Summary!$B13,'MAIN DATABASE'!$J:$J,Summary!K$2) -> #REF! | L13: =SUMIFS('MAIN DATABASE'!#REF!,'MAIN DATABASE'!$F:$F,Summary!$B13,'MAIN DATABASE'!$J:$J,Summary!L$2) -> #REF! | M13: =SUMIFS('MAIN DATABASE'!#REF!,'MAIN DATABASE'!$F:$F,Summary!$B13,'MAIN DATABASE'!$J:$J,Summary!M$2) -> #REF! | N13: =SUMIFS('MAIN DATABASE'!#REF!,'MAIN DATABASE'!$F:$F,Summary!$B13,'MAIN DATABASE'!$J:$J,Summary!N$2) -> #REF! | O13: =SUMIFS('MAIN DATABASE'!#REF!,'MAIN DATABASE'!$F:$F,Summary!$B13,'MAIN DATABASE'!$J:$J,Summary!O$2) -> #REF! | P13: =SUMIFS('MAIN DATABASE'!#REF!,'MAIN DATABASE'!$F:$F,Summary!$B13,'MAIN DATABASE'!$J:$J,Summary!P$2) -> #REF! | Q13: =SUMIFS('MAIN DATABASE'!#REF!,'MAIN DATABASE'!$F:$F,Summary!$B13,'MAIN DATABASE'!$J:$J,Summary!Q$2) -> #REF! | R13: =SUM(J13:O13) -> #REF! | S13: =P13+Q13 -> #REF! | T13: =R13+S13 -> #REF! | U13: =I13-R13 -> #REF!
B14: KALIHATI | I14: =SUM(C14:H14) -> 0 | J14: =SUMIFS('MAIN DATABASE'!#REF!,'MAIN DATABASE'!$F:$F,Summary!$B14,'MAIN DATABASE'!$J:$J,Summary!J$2) -> #REF! | K14: =SUMIFS('MAIN DATABASE'!#REF!,'MAIN DATABASE'!$F:$F,Summary!$B14,'MAIN DATABASE'!$J:$J,Summary!K$2) -> #REF! | L14: =SUMIFS('MAIN DATABASE'!#REF!,'MAIN DATABASE'!$F:$F,Summary!$B14,'MAIN DATABASE'!$J:$J,Summary!L$2) -> #REF! | M14: =SUMIFS('MAIN DATABASE'!#REF!,'MAIN DATABASE'!$F:$F,Summary!$B14,'MAIN DATABASE'!$J:$J,Summary!M$2) -> #REF! | N14: =SUMIFS('MAIN DATABASE'!#REF!,'MAIN DATABASE'!$F:$F,Summary!$B14,'MAIN DATABASE'!$J:$J,Summary!N$2) -> #REF! | O14: =SUMIFS('MAIN DATABASE'!#REF!,'MAIN DATABASE'!$F:$F,Summary!$B14,'MAIN DATABASE'!$J:$J,Summary!O$2) -> #REF! | P14: =SUMIFS('MAIN DATABASE'!#REF!,'MAIN DATABASE'!$F:$F,Summary!$B14,'MAIN DATABASE'!$J:$J,Summary!P$2) -> #REF! | Q14: =SUMIFS('MAIN DATABASE'!#REF!,'MAIN DATABASE'!$F:$F,Summary!$B14,'MAIN DATABASE'!$J:$J,Summary!Q$2) -> #REF! | R14: =SUM(J14:O14) -> #REF! | S14: =P14+Q14 -> #REF! | T14: =R14+S14 -> #REF! | U14: =I14-R14 -> #REF!
... B25: SHAMGANJ | I25: =SUM(C25:H25) -> 0 | J25: =SUMIFS('MAIN DATABASE'!#REF!,'MAIN DATABASE'!$F:$F,Summary!$B25,'MAIN DATABASE'!$J:$J,Summary!J$2) -> #REF! | K25: =SUMIFS('MAIN DATABASE'!#REF!,'MAIN DATABASE'!$F:$F,Summary!$B25,'MAIN DATABASE'!$J:$J,Summary!K$2) -> #REF! | L25: =SUMIFS('MAIN DATABASE'!#REF!,'MAIN DATABASE'!$F:$F,Summary!$B25,'MAIN DATABASE'!$J:$J,Summary!L$2) -> #REF! | M25: =SUMIFS('MAIN DATABASE'!#REF!,'MAIN DATABASE'!$F:$F,Summary!$B25,'MAIN DATABASE'!$J:$J,Summary!M$2) -> #REF! | N25: =SUMIFS('MAIN DATABASE'!#REF!,'MAIN DATABASE'!$F:$F,Summary!$B25,'MAIN DATABASE'!$J:$J,Summary!N$2) -> #REF! | O25: =SUMIFS('MAIN DATABASE'!#REF!,'MAIN DATABASE'!$F:$F,Summary!$B25,'MAIN DATABASE'!$J:$J,Summary!O$2) -> #REF! | P25: =SUMIFS('MAIN DATABASE'!#REF!,'MAIN DATABASE'!$F:$F,Summary!$B25,'MAIN DATABASE'!$J:$J,Summary!P$2) -> #REF! | Q25: =SUMIFS('MAIN DATABASE'!#REF!,'MAIN DATABASE'!$F:$F,Summary!$B25,'MAIN DATABASE'!$J:$J,Summary!Q$2) -> #REF! | R25: =SUM(J25:O25) -> #REF! | S25: =P25+Q25 -> #REF! | T25: =R25+S25 -> #REF! | U25: =I25-R25 -> #REF!
